<?xml version="1.0"?>
<robot xmlns:xacro="http://wiki.ros.org/xacro">

  <xacro:property name="DEG2RAD" value="0.017453292519943295"/>

  <xacro:macro name="kuka_kr90r2900_extraha" params="prefix">
    <!--xacro:unless value="${not connected_to}">
      <joint name="${prefix}_joint_${connected_to}" type="fixed">
        <parent link="${connected_to}"/>
        <child link="${prefix}_base_link"/>
        <origin rpy="${rpy}" xyz="${xyz}"/>
      </joint>
    </xacro:unless-->
    <!-- LINKS -->
    <!-- base link -->
    <link name="${prefix}base_link">
      <!--inertial>
        <origin xyz="0 0 0" rpy="0 0 0"/>
        <mass value="2"/>
        <inertia ixx="0.01" ixy="0" ixz="0" iyy="0.01" iyz="0" izz="0.01" />
      </inertial-->
      <visual>
        <origin xyz="0 0 0" rpy="0 0 0"/>
        <geometry>
          <mesh filename="package://kuka_kr90_support/meshes/kr90r2900extraHA/visual/base_link.dae" />
        </geometry>
      </visual>
      <collision>
        <origin xyz="0 0 0" rpy="0 0 0"/>
        <geometry>
          <mesh filename="package://kuka_kr90_support/meshes/kr90r2900extraHA/collision/base_link.stl" />
        </geometry>
      </collision>
    </link>
    <!-- link 1 (A1) -->
    <link name="${prefix}link_1">
      <!--inertial>
        <origin xyz="0 0 -0.675" rpy="0 0 0"/>
        <mass value="2"/>
        <inertia ixx="0.01" ixy="0" ixz="0" iyy="0.01" iyz="0" izz="0.01" />
      </inertial-->
      <visual>
        <origin xyz="0 0 -0.675" rpy="0 0 0"/>
        <geometry>
          <mesh filename="package://kuka_kr90_support/meshes/kr90r2900extraHA/visual/link_1.dae" />
        </geometry>
      </visual>
      <collision>
        <origin xyz="0 0 -0.675" rpy="0 0 0"/>
        <geometry>
          <mesh filename="package://kuka_kr90_support/meshes/kr90r2900extraHA/collision/link_1.stl" />
        </geometry>
      </collision>
    </link>
    <!-- link 2 -->
    <link name="${prefix}link_2">
      <!--inertial>
        <origin xyz="-0.675 0 0.35" rpy="0 1.571 0"/>
        <mass value="2"/>
        <inertia ixx="0.01" ixy="0" ixz="0" iyy="0.01" iyz="0" izz="0.01" />
      </inertial-->
      <visual>
        <origin xyz="-0.675 0 0.35" rpy="0 1.571 0"/>
        <geometry>
          <mesh filename="package://kuka_kr90_support/meshes/kr90r2900extraHA/visual/link_2.dae"/>
        </geometry>
      </visual>
      <collision>
        <origin xyz="-0.675 0 0.35" rpy="0 1.571 0"/>
        <geometry>
          <mesh filename="package://kuka_kr90_support/meshes/kr90r2900extraHA/collision/link_2.stl" />
        </geometry>
      </collision>
    </link>
    <!-- link 3 -->
    <link name="${prefix}link_3">
      <!--inertial>
        <origin xyz="-0.35 0 -2.025" rpy="0 0 0"/>
        <mass value="2"/>
        <inertia ixx="0.01" ixy="0" ixz="0" iyy="0.01" iyz="0" izz="0.01" />
      </inertial-->
      <visual>
        <origin xyz="-0.35 0 -2.025" rpy="0 0 0"/>
        <geometry>
          <mesh filename="package://kuka_kr90_support/meshes/kr90r2900extraHA/visual/link_3.dae" />
        </geometry>
      </visual>
      <collision>
        <origin xyz="-0.35 0 -2.025" rpy="0 0 0"/>
        <geometry>
          <mesh filename="package://kuka_kr90_support/meshes/kr90r2900extraHA/collision/link_3.stl" />
        </geometry>
      </collision>
    </link>
    <!-- link 4 -->
    <link name="${prefix}link_4">
      <!--inertial>
        <origin xyz="-0.35 0 -1.984" rpy="0 0 0"/>
        <mass value="2"/>
        <inertia ixx="0.01" ixy="0" ixz="0" iyy="0.01" iyz="0" izz="0.01" />
      </inertial-->
      <visual>
        <origin xyz="-0.35 0 -1.984" rpy="0 0 0"/>
        <geometry>
          <mesh filename="package://kuka_kr90_support/meshes/kr90r2900extraHA/visual/link_4.dae" />
        </geometry>
      </visual>
      <collision>
        <origin xyz="-0.35 0 -1.984" rpy="0 0 0"/>
        <geometry>
          <mesh filename="package://kuka_kr90_support/meshes/kr90r2900extraHA/collision/link_4.stl" />
        </geometry>
      </collision>
    </link>
    <!-- link 5 -->
    <link name="${prefix}link_5">
      <!--inertial>
        <origin xyz="-1.55 0 -1.984" rpy="0 0 0"/>
        <mass value="2"/>
        <inertia ixx="0.01" ixy="0" ixz="0" iyy="0.01" iyz="0" izz="0.01" />
      </inertial-->
      <visual>
        <origin xyz="-1.55 0 -1.984" rpy="0 0 0"/>
        <geometry>
          <mesh filename="package://kuka_kr90_support/meshes/kr90r2900extraHA/visual/link_5.dae" />
        </geometry>
      </visual>
      <collision>
        <origin xyz="-1.55 0 -1.984" rpy="0 0 0"/>
        <geometry>
          <mesh filename="package://kuka_kr90_support/meshes/kr90r2900extraHA/collision/link_5.stl" />
        </geometry>
      </collision>
    </link>
    <!-- link 6 -->
    <link name="${prefix}link_6">
      <!--inertial>
        <origin xyz="-1.55 0 -1.984" rpy="0 0 0"/>
        <mass value="2"/>
        <inertia ixx="0.01" ixy="0" ixz="0" iyy="0.01" iyz="0" izz="0.01" />
      </inertial-->
      <visual>
        <origin xyz="-1.765 0 -1.984" rpy="0 0 0"/>
        <geometry>
          <mesh filename="package://kuka_kr90_support/meshes/kr90r2900extraHA/visual/link_6.dae" />
        </geometry>
      </visual>
      <collision>
        <origin xyz="-1.765 0 -1.984" rpy="0 0 0"/>
        <geometry>
          <mesh filename="package://kuka_kr90_support/meshes/kr90r2900extraHA/collision/link_6.stl" />
        </geometry>
      </collision>
    </link>
    <!-- tool 0 -->
    <!-- This frame corresponds to the $FLANGE coordinate system in KUKA KRC controllers. -->
    <link name="${prefix}tool0">
      <visual>
        <!-- old torch origin xyz="0.0216 0 -0.4853" rpy="${DEG2RAD * 180} 0 0"/-->  
        <origin xyz="0.001 0 -0.4727" rpy="${DEG2RAD * 180} 0 0"/>
        <geometry>
          <mesh filename="package://kuka_kr90_support/meshes/kr90r2900extraHA/visual/tocha.dae" />
        </geometry>
      </visual>
      <!--collision>
        <origin xyz="0.001 0 -0.4727" rpy="${DEG2RAD * 180} 0 0"/>
        <geometry>
          <mesh filename="package://kuka_kr90_support/meshes/kr90r2900extraHA/collision/tocha.stl" />
        </geometry>
      </collision-->
    </link>
    <!-- END LINKS -->

    <!-- JOINTS -->
    <!-- joint 1 (A1) -->
    <joint name="${prefix}joint_a1" type="revolute">
      <origin xyz="0 0 0.675" rpy="0 0 0"/>
      <parent link="${prefix}base_link"/>
      <child link="${prefix}link_1"/>
      <axis xyz="0 0 -1"/>
      <limit effort="0" lower="${-DEG2RAD * 185}" upper="${DEG2RAD * 185}" velocity="${DEG2RAD * 105}"/>
    </joint>
    <!-- joint 2 (A2) -->
    <joint name="${prefix}joint_a2" type="revolute">
      <origin xyz="0.35 0 0" rpy="0 0 0"/>
      <parent link="${prefix}link_1"/>
      <child link="${prefix}link_2"/>
      <axis xyz="0 1 0"/>
      <limit effort="0" lower="${-DEG2RAD * 140}" upper="${DEG2RAD * 140}" velocity="${DEG2RAD * 101}"/>
    </joint>
    <!-- joint 3 (A3) -->
    <joint name="${prefix}joint_a3" type="revolute">
      <origin xyz="1.35 0 0" rpy="0 0 0"/>
      <parent link="${prefix}link_2"/>
      <child link="${prefix}link_3"/>
      <axis xyz="0 1 0"/>
      <limit effort="0" lower="${-DEG2RAD * 120}" upper="${DEG2RAD * 155}" velocity="${DEG2RAD * 107}"/>
    </joint>
    <!-- joint 4 (A4) -->
    <joint name="${prefix}joint_a4" type="revolute">
      <origin xyz="0 0 -0.041" rpy="0 0 0"/>
      <parent link="${prefix}link_3"/>
      <child link="${prefix}link_4"/>
      <axis xyz="-1 0 0"/>
      <limit effort="0" lower="${-DEG2RAD * 350}" upper="${DEG2RAD * 350}" velocity="${DEG2RAD * 292}"/>
    </joint>
    <!-- joint 5 (A5) -->
    <joint name="${prefix}joint_a5" type="revolute">
      <origin xyz="1.2 0 0" rpy="0 0 0"/>
      <parent link="${prefix}link_4"/>
      <child link="${prefix}link_5"/>
      <axis xyz="0 1 0"/>
      <limit effort="0" lower="${-DEG2RAD * 125}" upper="${DEG2RAD * 125}" velocity="${DEG2RAD * 258}"/>
    </joint>
    <!-- joint 6 (A6) -->
    <joint name="${prefix}joint_a6" type="revolute">
      <origin xyz="0.215 0 0" rpy="0 0 0"/>
      <parent link="${prefix}link_5"/>
      <child link="${prefix}link_6"/>
      <axis xyz="-1 0 0"/>
      <limit effort="0" lower="${-DEG2RAD * 350}" upper="${DEG2RAD * 350}" velocity="${DEG2RAD * 284}"/>
    </joint>
    <!-- tool frame - fixed frame -->
    <joint name="${prefix}joint_a6-tool0" type="fixed">
      <parent link="${prefix}link_6"/>
      <child link="${prefix}tool0"/>
      <origin xyz="0.4727 0 0.001" rpy="0 ${DEG2RAD * 90} 0"/>
      <axis xyz="0 0 -1"/>
    </joint>
    <!-- END JOINTS -->

    <!-- ROS base_link to KUKA $ROBROOT coordinate system transform -->
    <!--link name="${prefix}base" />
    <joint name="${prefix}base_link-base" type="fixed">
      <origin xyz="0 0 0" rpy="0 0 0"/>
      <parent link="${prefix}base_link"/>
      <child link="${prefix}base"/>
    </joint-->

  </xacro:macro>
</robot>


