<?xml version="1.0" encoding="utf-8"?>
<!-- =================================================================================== -->
<!-- |    This document was autogenerated by xacro from kp2hv1100_hw.xacro             | -->
<!-- |    EDITING THIS FILE BY HAND IS NOT RECOMMENDED                                 | -->
<!-- =================================================================================== -->
<!--Generates a urdf from the macro in kp2hv1100_hw_macro.xacro -->
<robot name="kuka_kp2hv1100_hw">
  <!-- LINKS -->
  <!-- base link -->
  <link name="kp2_base_link">
    <!--inertial>
        <origin xyz="0 0 0" rpy="0 0 0"/>
        <mass value="2"/>
        <inertia ixx="0.01" ixy="0" ixz="0" iyy="0.01" iyz="0" izz="0.01" />
      </inertial-->
    <visual>
      <origin rpy="0 0 0" xyz="0 0 0"/>
      <geometry>
        <mesh filename="package://kuka_kp2_support/meshes/kp2hv1100HW/visual/base_link.dae"/>
      </geometry>
    </visual>
    <collision>
      <origin rpy="0 0 0" xyz="0 0 0"/>
      <geometry>
        <mesh filename="package://kuka_kp2_support/meshes/kp2hv1100HW/collision/base_link.stl"/>
      </geometry>
    </collision>
  </link>
  <!-- link 1 (A1) -->
  <link name="kp2_link_1">
    <inertial>
      <origin rpy="0 0 0" xyz="0 -0.77 -0.865"/>
      <mass value="2"/>
      <inertia ixx="0.01" ixy="0" ixz="0" iyy="0.01" iyz="0" izz="0.01"/>
    </inertial>
    <visual>
      <origin rpy="0 0 0" xyz="0 -0.770 -0.865"/>
      <geometry>
        <mesh filename="package://kuka_kp2_support/meshes/kp2hv1100HW/visual/link_1.dae"/>
      </geometry>
    </visual>
    <collision>
      <origin rpy="0 0 0" xyz="0 -0.77 -0.865"/>
      <geometry>
        <mesh filename="package://kuka_kp2_support/meshes/kp2hv1100HW/collision/link_1.stl"/>
      </geometry>
    </collision>
  </link>
  <!-- link 2 -->
  <link name="kp2_link_2">
    <inertial>
      <origin rpy="0 0 0" xyz="0 -0.770 -1.085"/>
      <mass value="2"/>
      <inertia ixx="0.01" ixy="0" ixz="0" iyy="0.01" iyz="0" izz="0.01"/>
    </inertial>
    <visual>
      <origin rpy="0 0 0" xyz="0 -0.770 -1.085"/>
      <geometry>
        <mesh filename="package://kuka_kp2_support/meshes/kp2hv1100HW/visual/link_2.dae"/>
      </geometry>
    </visual>
    <collision>
      <origin rpy="0 0 0" xyz="0 -0.770 -1.085"/>
      <geometry>
        <mesh filename="package://kuka_kp2_support/meshes/kp2hv1100HW/collision/link_2.stl"/>
      </geometry>
    </collision>
  </link>
  <link name="kp2_tool0"/>
  <!-- END LINKS -->
  <!-- JOINTS -->
  <!-- joint 1 (A1) -->
  <joint name="kp2_joint_a1" type="revolute">
    <origin rpy="0 0 0" xyz="0 0.770 0.865"/>
    <parent link="kp2_base_link"/>
    <child link="kp2_link_1"/>
    <axis xyz="1 0 0"/>
    <limit effort="0" lower="-3.22885911619" upper="3.22885911619" velocity="1.83259571459"/>
  </joint>
  <!-- joint 2 (A2) -->
  <joint name="kp2_joint_a2" type="revolute">
    <origin rpy="0 0 0" xyz="0 0 0.22"/>
    <!--For an aligned coordinate system for the plate use rpy="0 0 1.2653638"-->
    <parent link="kp2_link_1"/>
    <child link="kp2_link_2"/>
    <axis xyz="0 0 1"/>
    <limit effort="0" lower="-2.44346095279" upper="-0.0872664625997" velocity="1.76278254451"/>
  </joint>
  <!-- tool frame - fixed frame -->
  <joint name="kp2_joint_a2-tool0" type="fixed">
    <parent link="kp2_link_2"/>
    <child link="kp2_tool0"/>
    <origin rpy="0 0 0" xyz="0 0 0"/>
  </joint>
  <!-- END JOINTS -->
  <!-- ROS base_link to KUKA $ROBROOT coordinate system transform -->
  <link name="kp2_base"/>
  <joint name="kp2_base_link-base" type="fixed">
    <origin rpy="0 0 0" xyz="0 0 0"/>
    <parent link="kp2_base_link"/>
    <child link="kp2_base"/>
  </joint>
</robot>
